## 分类

> 1. 检查性异常
> 2. 运行时异常
> 3. 错误error

#### Error

> 1. error类对象由java虚拟机生成并抛出，大多数错误与代码编写者所执行的操作无关
> 2. 内存异常，jvm会终止线程(OutOfMemoryError)
> 3. 定义错误(NoClassDefFoundError)、链接错误(LinkageError)。这些错误不可检查，因为他们再应用程序的控制和处理能力之外，而且绝大多数是程序运行时不允许出现的状况。

#### Exception

- Exception分支中有一个重要的子类==RuntimeException(运行时异常)==

> 1. ArrayIndexOutOfBoundsException(数组下标越界)
> 2. NullPointerException)(空指针异常)
> 3. ArithmeticException(算术异常)
> 4. MissingResourceExceotion(丢失资源)
> 5. ClassNotFoundException(找不到类)
>
> 这些异常是不检查异常，程序中可以选择捕获处理，也可以不处理



## 异常处理

#### 常见需要异常处理的

> 用户打开文件

#### 语法

- 多个异常从小到大

```java
/**
 * 代码 1
 */
public class Demo01 {
    public static void main(String[] args) {
        int a = 1;
        int b = 0;
        try {
            System.out.println(a/b);
        } catch (ArithmeticException e) { //异常捕获小范围在前
            System.out.println("算术异常");
        } catch (Exception e){  //异常捕获大范围在后，如果前面catch捕获异常成功，不执行
            System.out.println("后执行异常捕获");
        }finally { //先执行try catch，后执行finally：正常情况下
            System.out.println("善后处理");
        }
    }
}
```

#### finally 《 The Java Tutorials 》文档

> The finally block ==always executes when the try block exits==. This ensures that the finally block is executed even if an unexpected exception occurs. But finally is useful for more than just exception handling — it allows the programmer to avoid having ==cleanup code== accidentally bypassed by a `return`,`continue`, or` break`. Putting cleanup code in a finally block is always a good practice, even when no exceptions are anticipated. 
>
> Note: If the==JVM exits== while the try or catch code is being executed, then the finally block may not execute. Likewise, if the thread executing the try or catch code is interrupted or killed, the finally block may not execute even though the application as a whole continues.

#### finally不执行的情况

1. try 语句块之前返回（return）或者抛出异常，所以 try 对应的 finally 语句块没有执行。

```java
/**
 * 代码 2
 */
public class Demo01 {
    public static void main(String[] args) {
        System.out.println("return value of test(): " + test());
    }

    public static int test() {
        int i = 1;
        if(i == 1)
        	return 0;//注释不执行，会在 i = i / 0;算术溢出，不执行try语句块
        System.out.println("the previous statement of try block");
        i = i / 0;
        try {
            System.out.println("try block");
            return i;
        }finally {
            System.out.println("finally block");
        }
    }
}
```

2. try语句块执行中终止了虚拟机运行
   1. try 语句块中执行了 System.exit (0) 语句，终止了 Java 虚拟机的运行
   2. 当一个线程在执行 try 语句块或者 catch 语句块时被打断（interrupted）或者被终止（killed），与其相对应的 finally 语句块可能不会执行
   3. 在线程运行 try 语句块或者 catch 语句块时，突然死机或者断电，finally 语句块肯定不会执行了

#### try catch finally执行顺序

##### Java 语言规范第四版《The Java™ Programming Language, Fourth Edition》

> You catch exceptions by enclosing code in Try blocks. The basic syntax for a Try block is:

```java
/**
 * 代码 3
 */
try {
    statements
} catch (exception_type1 identifier1) {
    statements
} catch (exception_type2 identifier2) {
    statements
        ...
} finally {
    statements
}
```

> where either at least one catch clause, or the finally clause, must be present. The body of the try statement is executed until either an exception is thrown or the body finishes successfully. If an exception is thrown, each catch clause is examined in turn, from first to last, to see whether the type of the exception object is assignable to the type declared in the catch. When an assignable catch clause is found, its block is executed with its identifier set to reference the exception object. No other catch clause will be executed. Any number of catch clauses, including zero, can be associated with a particular TRy as long as each clause catches a different type of exception. If no appropriate catch is found, the exception percolates out of the try statement into any outer try that might have a catch clause to handle it. 

> If a finally clause is present with a try, its code is executed after all other processing in the try is complete. This happens no matter how completion was achieved, whether normally, through an exception, or through a control flow statement such as return or break .

> A finally clause can also be used to clean up for break , continue , and return , which is one reason you will sometimes see a try clause with no catch clauses. When any control transfer statement is executed, all relevant finally clauses are executed. There is no way to leave a try block without executing its finally clause.

##### 存在控制转移语句return、break、continue、throw

###### 区别

> return 和 throw 把程序控制权转交给它们的调用者（invoker），而 break 和 continue 的控制权是在当前方法内转移

###### return

> 1. finally 语句块在 try 语句块中的 return 语句之前执行
> 2. finally 语句块在 catch 语句块中的 return 语句之前执行

```java
/**
 * 代码 4
 */
public class Demo01 {
    public static void main(String[] args) {
        System.out
                .println("return value of getValue(): " + getValue
                        ());
    }

    public static int getValue() {
        try {
            return 0;
        } finally {
            return 1;
        }
    }
}
```

> 上面代码执行结果**return value of getValue(): 1**
>
> 根据上面内容很容易理解

```java
/**
 * 代码 5
 */
public static void main(String[] args) {
        System.out
                .println("return value of getValue(): " + getValue
                        ());
    }

    public static int getValue() {
        int i = 1;
        try {
            return i;
        } finally {
            i++;
        }
    }
```

> 上面代码执行结果**return value of getValue(): 1**
>
> 为什么结果不是2呢，需要理解 JVM对finally的编译

> 关于 Java 虚拟机是如何编译 finally 语句块的问题，有兴趣的读者可以参考《 The JavaTM Virtual Machine Specification, Second Edition 》中 7.13 节 Compiling finally。那里详细介绍了 Java 虚拟机是如何编译 finally 语句块。实际上，Java 虚拟机会把 finally 语句块作为 subroutine（对于这个 subroutine 不知该如何翻译为好，干脆就不翻译了，免得产生歧义和误解。）直接插入到 try 语句块或者 catch 语句块的控制转移语句之前。但是，还有另外一个不可忽视的因素，那就是在执行 subroutine（也就是 finally 语句块）之前，try 或者 catch 语句块会保留其返回值到本地变量表（Local Variable Table）中。待 subroutine 执行完毕之后，再恢复保留的返回值到操作数栈中，然后通过 return 或者 throw 语句将其返回给该方法的调用者（invoker）。请注意，前文中我们曾经提到过 return、throw 和 break、continue 的区别，对于这条规则（保留返回值），只适用于 return 和 throw 语句，不适用于 break 和 continue 语句，因为它们根本就没有返回值

- 根据《 The JavaTM Virtual Machine Specification, Second Edition 》中的解释，我们查看编译的字节码反编译文件可以看到编译结果如下

```java
/**
 * 代码 5 反编译文件
 */
public class Demo01 {
    public Demo01() {
    }

    public static void main(String[] args) {
        System.out.println("return value of getValue(): " + getValue());
    }

    public static int getValue() {
        byte i = 1;

        byte var1;
        try {
            var1 = i;
        } finally {
            int var5 = i + 1;
        }

        return var1;//返回var1而不是 var5
    }
}
```

```java
/**
 * 代码 4 反编译文件
 */
public class Demo01 {
    public Demo01() {
    }

    public static void main(String[] args) {
        System.out.println("return value of getValue(): " + getValue());
    }

    public static int getValue() {
        try {
            boolean var0 = false;
            return 1;//直接返回 1 
        } finally {
            ;
        }
    }
}
```

- 复杂情况

```java
/**
 * 代码 6
 */
public class Demo01 {
    public static void main(String[] args) {
        System.out.println(test());
    }

    public static String test() {
        try {
            System.out.println("try block");	//执行顺序 1
            return test1();	//执行顺序 4 after return
        } finally {
            System.out.println("finally block");	//执行顺序 3
        }
    }

    public static String test1() {
        System.out.println("return statement");	//执行顺序 2
        return "after return";	//执行顺序 4
    }
}
```

> 执行结果
>
> try block
> return statement
> finally block
> after return

## 抛出异常



##### 抛出异常执行顺序